<?xml version="1.0" encoding="utf-8"?>
<!-- This URDF was automatically created by SolidWorks to URDF Exporter! Originally created by Stephen Brawner (brawner@gmail.com) 
     Commit Version: 1.6.0-4-g7f85cfe  Build Version: 1.6.7995.38578
     For more information, please see http://wiki.ros.org/sw_urdf_exporter -->
<robot
  name="TLA_Spider.SLDASM">
  <link
    name="base_link">
    <inertial>
      <origin
        xyz="0.0266892943143008 0.0363292392541809 0.0529146307622766"
        rpy="0 0 0" />
      <mass
        value="0.0921702413076557" />
      <inertia
        ixx="2.08625964058626E-05"
        ixy="-4.27199153295138E-13"
        ixz="3.28311314709021E-11"
        iyy="3.53797936296955E-05"
        iyz="-1.5085365891341E-11"
        izz="2.06809503924717E-05" />
    </inertial>
    <visual>
      <origin
        xyz="0 0 0"
        rpy="0 0 0" />
      <geometry>
        <mesh
          filename="package://TLA_Spider.SLDASM/meshes/base_link.STL" />
      </geometry>
      <material
        name="">
        <color
          rgba="0.752941176470588 0.752941176470588 0.752941176470588 1" />
      </material>
    </visual>
    <collision>
      <origin
        xyz="0 0 0"
        rpy="0 0 0" />
      <geometry>
        <mesh
          filename="package://TLA_Spider.SLDASM/meshes/base_link.STL" />
      </geometry>
    </collision>
  </link>
  <link
    name="Leg_upper_1">
    <inertial>
      <origin
        xyz="0.0219695652013671 0.0182206042868569 0.00306928262534811"
        rpy="0 0 0" />
      <mass
        value="0.0248043828707764" />
      <inertia
        ixx="1.11700647610023E-06"
        ixy="9.55168830429846E-08"
        ixz="5.16996811332449E-08"
        iyy="2.82437786068354E-06"
        iyz="1.10330416179466E-08"
        izz="2.13843485239965E-06" />
    </inertial>
    <visual>
      <origin
        xyz="0 0 0"
        rpy="0 0 0" />
      <geometry>
        <mesh
          filename="package://TLA_Spider.SLDASM/meshes/Leg_upper_1.STL" />
      </geometry>
      <material
        name="">
        <color
          rgba="0.752941176470588 0.752941176470588 0.752941176470588 1" />
      </material>
    </visual>
    <collision>
      <origin
        xyz="0 0 0"
        rpy="0 0 0" />
      <geometry>
        <mesh
          filename="package://TLA_Spider.SLDASM/meshes/Leg_upper_1.STL" />
      </geometry>
    </collision>
  </link>
  <joint
    name="Leg_upper_1"
    type="continuous">
    <origin
      xyz="0.0558314237945942 -0.082056810538703 0.0322574126580789"
      rpy="1.5707963267949 0 -0.770351507810951" />
    <parent
      link="base_link" />
    <child
      link="Leg_upper_1" />
    <axis
      xyz="0 1 0" />
  </joint>
  <link
    name="Lever_1">
    <inertial>
      <origin
        xyz="0.000137732744342312 -0.00939613235642105 -0.00404716546866996"
        rpy="0 0 0" />
      <mass
        value="0.00522501118381082" />
      <inertia
        ixx="1.49572193703694E-07"
        ixy="-1.08598986359122E-11"
        ixz="-4.0419407716901E-10"
        iyy="2.33200764441941E-07"
        iyz="-7.80735371769024E-12"
        izz="1.00631895775878E-07" />
    </inertial>
    <visual>
      <origin
        xyz="0 0 0"
        rpy="0 0 0" />
      <geometry>
        <mesh
          filename="package://TLA_Spider.SLDASM/meshes/Lever_1.STL" />
      </geometry>
      <material
        name="">
        <color
          rgba="0.752941176470588 0.752941176470588 0.752941176470588 1" />
      </material>
    </visual>
    <collision>
      <origin
        xyz="0 0 0"
        rpy="0 0 0" />
      <geometry>
        <mesh
          filename="package://TLA_Spider.SLDASM/meshes/Lever_1.STL" />
      </geometry>
    </collision>
  </link>
  <joint
    name="Lever_1"
    type="continuous">
    <origin
      xyz="0.024594 0.02115 0"
      rpy="1.5708 0 0.56575" />
    <parent
      link="Leg_upper_1" />
    <child
      link="Lever_1" />
    <axis
      xyz="0 1 0" />
  </joint>
  <link
    name="Shaft_1">
    <inertial>
      <origin
        xyz="0.00229998756333495 5.76205749780456E-14 -0.0209999999999994"
        rpy="0 0 0" />
      <mass
        value="0.000924746069982422" />
      <inertia
        ixx="2.16771891835994E-07"
        ixy="2.1713491079517E-23"
        ixz="-5.15617864956101E-20"
        iyy="2.15544270402288E-07"
        iyz="5.83430726109264E-19"
        izz="3.69361095365845E-09" />
    </inertial>
    <visual>
      <origin
        xyz="0 0 0"
        rpy="0 0 0" />
      <geometry>
        <mesh
          filename="package://TLA_Spider.SLDASM/meshes/Shaft_1.STL" />
      </geometry>
      <material
        name="">
        <color
          rgba="0.501960784313725 1 0.501960784313725 1" />
      </material>
    </visual>
    <collision>
      <origin
        xyz="0 0 0"
        rpy="0 0 0" />
      <geometry>
        <mesh
          filename="package://TLA_Spider.SLDASM/meshes/Shaft_1.STL" />
      </geometry>
    </collision>
  </link>
  <joint
    name="Shaft_1"
    type="prismatic">
    <origin
      xyz="0.036019 0 0.0047263"
      rpy="-1.0306 0 -1.5708" />
    <parent
      link="Lever_1" />
    <child
      link="Shaft_1" />
    <axis
      xyz="1 0 0" />
    <limit
      lower="0"
      upper="0"
      effort="0"
      velocity="0" />
  </joint>
  <link
    name="Leg_lower_1">
    <inertial>
      <origin
        xyz="0.00210000000002336 -9.15195454093132E-06 -0.0353242430383387"
        rpy="0 0 0" />
      <mass
        value="0.00511403475106288" />
      <inertia
        ixx="3.40097557199022E-06"
        ixy="-4.2351647362715E-22"
        ixz="2.63043434791863E-21"
        iyy="3.28327036320466E-06"
        iyz="1.35078946160938E-07"
        izz="1.31342634788394E-07" />
    </inertial>
    <visual>
      <origin
        xyz="0 0 0"
        rpy="0 0 0" />
      <geometry>
        <mesh
          filename="package://TLA_Spider.SLDASM/meshes/Leg_lower_1.STL" />
      </geometry>
      <material
        name="">
        <color
          rgba="0 1 1 1" />
      </material>
    </visual>
    <collision>
      <origin
        xyz="0 0 0"
        rpy="0 0 0" />
      <geometry>
        <mesh
          filename="package://TLA_Spider.SLDASM/meshes/Leg_lower_1.STL" />
      </geometry>
    </collision>
  </link>
  <joint
    name="Leg_lower_1"
    type="fixed">
    <origin
      xyz="0 0 0"
      rpy="1.9869 0 -3.1416" />
    <parent
      link="Shaft_1" />
    <child
      link="Leg_lower_1" />
    <axis
      xyz="0 0 0" />
  </joint>
  <link
    name="Leg_upper_2">
    <inertial>
      <origin
        xyz="0.0219724515584532 0.0182206044271985 -0.00309811153709386"
        rpy="0 0 0" />
      <mass
        value="0.0248043825976127" />
      <inertia
        ixx="1.11700647729267E-06"
        ixy="9.56337908812338E-08"
        ixz="-4.96044598039577E-08"
        iyy="2.82437783811212E-06"
        iyz="-1.10172036967586E-08"
        izz="2.13843482921062E-06" />
    </inertial>
    <visual>
      <origin
        xyz="0 0 0"
        rpy="0 0 0" />
      <geometry>
        <mesh
          filename="package://TLA_Spider.SLDASM/meshes/Leg_upper_2.STL" />
      </geometry>
      <material
        name="">
        <color
          rgba="0.752941176470588 0.752941176470588 0.752941176470588 1" />
      </material>
    </visual>
    <collision>
      <origin
        xyz="0 0 0"
        rpy="0 0 0" />
      <geometry>
        <mesh
          filename="package://TLA_Spider.SLDASM/meshes/Leg_upper_2.STL" />
      </geometry>
    </collision>
  </link>
  <joint
    name="Leg_upper_2"
    type="continuous">
    <origin
      xyz="-0.00245284745286619 -0.0820568105387026 0.0322574126580794"
      rpy="1.5707963267949 0 -2.34833207396482" />
    <parent
      link="base_link" />
    <child
      link="Leg_upper_2" />
    <axis
      xyz="0 1 0" />
  </joint>
  <link
    name="Lever_2">
    <inertial>
      <origin
        xyz="0.000137732744070695 0.00939505883879485 -0.00404716546895482"
        rpy="0 0 0" />
      <mass
        value="0.00522501118384892" />
      <inertia
        ixx="1.495721936999E-07"
        ixy="-1.08598984784832E-11"
        ixz="-4.04194076690804E-10"
        iyy="2.33200764442835E-07"
        iyz="-7.80735444168338E-12"
        izz="1.00631895780761E-07" />
    </inertial>
    <visual>
      <origin
        xyz="0 0 0"
        rpy="0 0 0" />
      <geometry>
        <mesh
          filename="package://TLA_Spider.SLDASM/meshes/Lever_2.STL" />
      </geometry>
      <material
        name="">
        <color
          rgba="0.752941176470588 0.752941176470588 0.752941176470588 1" />
      </material>
    </visual>
    <collision>
      <origin
        xyz="0 0 0"
        rpy="0 0 0" />
      <geometry>
        <mesh
          filename="package://TLA_Spider.SLDASM/meshes/Lever_2.STL" />
      </geometry>
    </collision>
  </link>
  <joint
    name="Lever_2"
    type="continuous">
    <origin
      xyz="0.024594 0.02115 0"
      rpy="1.5708 0 0.59052" />
    <parent
      link="Leg_upper_2" />
    <child
      link="Lever_2" />
    <axis
      xyz="0 1 0" />
  </joint>
  <link
    name="Shaft_2">
    <inertial>
      <origin
        xyz="-0.0022999875632927 5.91887650003287E-14 -0.0210000000000349"
        rpy="0 0 0" />
      <mass
        value="0.000924746069982422" />
      <inertia
        ixx="2.16771891835994E-07"
        ixy="1.03397576569128E-24"
        ixz="-6.20385459414771E-25"
        iyy="2.15544270402288E-07"
        iyz="2.20689202489734E-23"
        izz="3.69361095365839E-09" />
    </inertial>
    <visual>
      <origin
        xyz="0 0 0"
        rpy="0 0 0" />
      <geometry>
        <mesh
          filename="package://TLA_Spider.SLDASM/meshes/Shaft_2.STL" />
      </geometry>
      <material
        name="">
        <color
          rgba="0.501960784313725 1 0.501960784313725 1" />
      </material>
    </visual>
    <collision>
      <origin
        xyz="0 0 0"
        rpy="0 0 0" />
      <geometry>
        <mesh
          filename="package://TLA_Spider.SLDASM/meshes/Shaft_2.STL" />
      </geometry>
    </collision>
  </link>
  <joint
    name="Shaft_2"
    type="prismatic">
    <origin
      xyz="0.035614 0 0.0053891"
      rpy="-1.0121 0 -1.5708" />
    <parent
      link="Lever_2" />
    <child
      link="Shaft_2" />
    <axis
      xyz="1 0 0" />
    <limit
      lower="0"
      upper="0"
      effort="0"
      velocity="0" />
  </joint>
  <link
    name="Leg_lower_2">
    <inertial>
      <origin
        xyz="0.00199999999999963 -7.78388359218285E-06 -0.0300438332087714"
        rpy="0 0 0" />
      <mass
        value="0.00601286144806057" />
      <inertia
        ixx="3.40666556057306E-06"
        ixy="-1.05879118406788E-22"
        ixz="1.83634095986772E-21"
        iyy="3.28657694411922E-06"
        iyz="1.35078946160936E-07"
        izz="1.34649215702956E-07" />
    </inertial>
    <visual>
      <origin
        xyz="0 0 0"
        rpy="0 0 0" />
      <geometry>
        <mesh
          filename="package://TLA_Spider.SLDASM/meshes/Leg_lower_2.STL" />
      </geometry>
      <material
        name="">
        <color
          rgba="0.752941176470588 0.752941176470588 0.752941176470588 1" />
      </material>
    </visual>
    <collision>
      <origin
        xyz="0 0 0"
        rpy="0 0 0" />
      <geometry>
        <mesh
          filename="package://TLA_Spider.SLDASM/meshes/Leg_lower_2.STL" />
      </geometry>
    </collision>
  </link>
  <joint
    name="Leg_lower_2"
    type="fixed">
    <origin
      xyz="0.0041 0 0"
      rpy="1.996 0 3.1416" />
    <parent
      link="Shaft_2" />
    <child
      link="Leg_lower_2" />
    <axis
      xyz="0 0 0" />
  </joint>
  <link
    name="Leg_upper_3">
    <inertial>
      <origin
        xyz="0.0219695662103853 0.0182206040566766 0.00306928303355871"
        rpy="0 0 0" />
      <mass
        value="0.0248043815677668" />
      <inertia
        ixx="1.11700629001963E-06"
        ixy="9.55169681076297E-08"
        ixz="5.1699970567179E-08"
        iyy="2.82437776092305E-06"
        iyz="1.10330800439778E-08"
        izz="2.13843490661872E-06" />
    </inertial>
    <visual>
      <origin
        xyz="0 0 0"
        rpy="0 0 0" />
      <geometry>
        <mesh
          filename="package://TLA_Spider.SLDASM/meshes/Leg_upper_3.STL" />
      </geometry>
      <material
        name="">
        <color
          rgba="0.752941176470588 0.752941176470588 0.752941176470588 1" />
      </material>
    </visual>
    <collision>
      <origin
        xyz="0 0 0"
        rpy="0 0 0" />
      <geometry>
        <mesh
          filename="package://TLA_Spider.SLDASM/meshes/Leg_upper_3.STL" />
      </geometry>
    </collision>
  </link>
  <joint
    name="Leg_upper_3"
    type="continuous">
    <origin
      xyz="-0.00245284745286684 -0.0237725392912402 0.0322574126580794"
      rpy="1.5707963267949 0 2.44535194984566" />
    <parent
      link="base_link" />
    <child
      link="Leg_upper_3" />
    <axis
      xyz="0 1 0" />
  </joint>
  <link
    name="Lever_3">
    <inertial>
      <origin
        xyz="0.000137732741097914 -0.00939613235823964 -0.00404716546596748"
        rpy="0 0 0" />
      <mass
        value="0.00522501118887151" />
      <inertia
        ixx="1.49572193659465E-07"
        ixy="-1.08599013317567E-11"
        ixz="-4.04194077506601E-10"
        iyy="2.33200764432E-07"
        iyz="-7.80735644684694E-12"
        izz="1.00631895809334E-07" />
    </inertial>
    <visual>
      <origin
        xyz="0 0 0"
        rpy="0 0 0" />
      <geometry>
        <mesh
          filename="package://TLA_Spider.SLDASM/meshes/Lever_3.STL" />
      </geometry>
      <material
        name="">
        <color
          rgba="0.752941176470588 0.752941176470588 0.752941176470588 1" />
      </material>
    </visual>
    <collision>
      <origin
        xyz="0 0 0"
        rpy="0 0 0" />
      <geometry>
        <mesh
          filename="package://TLA_Spider.SLDASM/meshes/Lever_3.STL" />
      </geometry>
    </collision>
  </link>
  <joint
    name="Lever_3"
    type="continuous">
    <origin
      xyz="0.024594 0.02115 0"
      rpy="1.5708 0 0.80778" />
    <parent
      link="Leg_upper_3" />
    <child
      link="Lever_3" />
    <axis
      xyz="0 1 0" />
  </joint>
  <link
    name="Shaft_3">
    <inertial>
      <origin
        xyz="-0.00229998756330631 9.17321774096536E-15 -0.0210000000000089"
        rpy="0 0 0" />
      <mass
        value="0.000924746069982425" />
      <inertia
        ixx="2.16771891835994E-07"
        ixy="-2.48154183765908E-24"
        ixz="6.61744490042422E-24"
        iyy="2.15544270402289E-07"
        iyz="-2.54099544418633E-22"
        izz="3.69361095365844E-09" />
    </inertial>
    <visual>
      <origin
        xyz="0 0 0"
        rpy="0 0 0" />
      <geometry>
        <mesh
          filename="package://TLA_Spider.SLDASM/meshes/Shaft_3.STL" />
      </geometry>
      <material
        name="">
        <color
          rgba="0.501960784313725 1 0.501960784313725 1" />
      </material>
    </visual>
    <collision>
      <origin
        xyz="0 0 0"
        rpy="0 0 0" />
      <geometry>
        <mesh
          filename="package://TLA_Spider.SLDASM/meshes/Shaft_3.STL" />
      </geometry>
    </collision>
  </link>
  <joint
    name="Shaft_3"
    type="prismatic">
    <origin
      xyz="0 0 -0.016875"
      rpy="-2.2887 0 1.5708" />
    <parent
      link="Lever_3" />
    <child
      link="Shaft_3" />
    <axis
      xyz="1 0 0" />
    <limit
      lower="0"
      upper="0"
      effort="0"
      velocity="0" />
  </joint>
  <link
    name="Leg_lower_3">
    <inertial>
      <origin
        xyz="0.00200000000000873 -7.78388361417914E-06 -0.0300438332088237"
        rpy="0 0 0" />
      <mass
        value="0.00601286144806056" />
      <inertia
        ixx="3.40666556057306E-06"
        ixy="-9.95263713023803E-21"
        ixz="1.02922774897523E-19"
        iyy="3.2865769441197E-06"
        iyz="1.35078946155318E-07"
        izz="1.34649215702474E-07" />
    </inertial>
    <visual>
      <origin
        xyz="0 0 0"
        rpy="0 0 0" />
      <geometry>
        <mesh
          filename="package://TLA_Spider.SLDASM/meshes/Leg_lower_3.STL" />
      </geometry>
      <material
        name="">
        <color
          rgba="0.752941176470588 0.752941176470588 0.752941176470588 1" />
      </material>
    </visual>
    <collision>
      <origin
        xyz="0 0 0"
        rpy="0 0 0" />
      <geometry>
        <mesh
          filename="package://TLA_Spider.SLDASM/meshes/Leg_lower_3.STL" />
      </geometry>
    </collision>
  </link>
  <joint
    name="Leg_lower_3"
    type="fixed">
    <origin
      xyz="9.99999999978206E-05 0 -0.0420000000000199"
      rpy="-1.07775594280968 0 0" />
    <parent
      link="Shaft_3" />
    <child
      link="Leg_lower_3" />
    <axis
      xyz="0 0 0" />
  </joint>
  <link
    name="Leg_upper_4">
    <inertial>
      <origin
        xyz="0.0219724513836955 0.0182206044059165 -0.00309811158838733"
        rpy="0 0 0" />
      <mass
        value="0.0248043824392843" />
      <inertia
        ixx="1.11700645663666E-06"
        ixy="9.5633780592067E-08"
        ixz="-4.96044223449721E-08"
        iyy="2.82437782886804E-06"
        iyz="-1.10172081655124E-08"
        izz="2.13843483699474E-06" />
    </inertial>
    <visual>
      <origin
        xyz="0 0 0"
        rpy="0 0 0" />
      <geometry>
        <mesh
          filename="package://TLA_Spider.SLDASM/meshes/Leg_upper_4.STL" />
      </geometry>
      <material
        name="">
        <color
          rgba="0.752941176470588 0.752941176470588 0.752941176470588 1" />
      </material>
    </visual>
    <collision>
      <origin
        xyz="0 0 0"
        rpy="0 0 0" />
      <geometry>
        <mesh
          filename="package://TLA_Spider.SLDASM/meshes/Leg_upper_4.STL" />
      </geometry>
    </collision>
  </link>
  <joint
    name="Leg_upper_4"
    type="continuous">
    <origin
      xyz="0.055831423794595 -0.02377253929124 0.0322574126580794"
      rpy="1.5707963267949 0 0.800237564975585" />
    <parent
      link="base_link" />
    <child
      link="Leg_upper_4" />
    <axis
      xyz="0 1 0" />
  </joint>
  <link
    name="Lever_4">
    <inertial>
      <origin
        xyz="0.000137732744308783 0.00939505883875123 -0.00404716546880343"
        rpy="0 0 0" />
      <mass
        value="0.00522501118381655" />
      <inertia
        ixx="1.49572193703061E-07"
        ixy="-1.08598986089792E-11"
        ixz="-4.04194077088423E-10"
        iyy="2.33200764442093E-07"
        iyz="-7.80735383925932E-12"
        izz="1.00631895776696E-07" />
    </inertial>
    <visual>
      <origin
        xyz="0 0 0"
        rpy="0 0 0" />
      <geometry>
        <mesh
          filename="package://TLA_Spider.SLDASM/meshes/Lever_4.STL" />
      </geometry>
      <material
        name="">
        <color
          rgba="0.752941176470588 0.752941176470588 0.752941176470588 1" />
      </material>
    </visual>
    <collision>
      <origin
        xyz="0 0 0"
        rpy="0 0 0" />
      <geometry>
        <mesh
          filename="package://TLA_Spider.SLDASM/meshes/Lever_4.STL" />
      </geometry>
    </collision>
  </link>
  <joint
    name="Lever_4"
    type="continuous">
    <origin
      xyz="0.0245943670538191 0.0211500000000002 0"
      rpy="1.5707963267949 0 0.569899338365783" />
    <parent
      link="Leg_upper_4" />
    <child
      link="Lever_4" />
    <axis
      xyz="0 1 0" />
  </joint>
  <link
    name="Shaft_4">
    <inertial>
      <origin
        xyz="0.00229998756329507 5.41233724504764E-16 -0.0209999999999986"
        rpy="0 0 0" />
      <mass
        value="0.000924746069982424" />
      <inertia
        ixx="2.16771891835994E-07"
        ixy="0"
        ixz="-2.55392014125747E-23"
        iyy="2.15544270402289E-07"
        iyz="-9.6227600868913E-23"
        izz="3.69361095365842E-09" />
    </inertial>
    <visual>
      <origin
        xyz="0 0 0"
        rpy="0 0 0" />
      <geometry>
        <mesh
          filename="package://TLA_Spider.SLDASM/meshes/Shaft_4.STL" />
      </geometry>
      <material
        name="">
        <color
          rgba="0.501960784313725 1 0.501960784313725 1" />
      </material>
    </visual>
    <collision>
      <origin
        xyz="0 0 0"
        rpy="0 0 0" />
      <geometry>
        <mesh
          filename="package://TLA_Spider.SLDASM/meshes/Shaft_4.STL" />
      </geometry>
    </collision>
  </link>
  <joint
    name="Shaft_4"
    type="prismatic">
    <origin
      xyz="0 0 -0.016875"
      rpy="-2.1141 0 1.5708" />
    <parent
      link="Lever_4" />
    <child
      link="Shaft_4" />
    <axis
      xyz="1 0 0" />
    <limit
      lower="0"
      upper="0"
      effort="0"
      velocity="0" />
  </joint>
  <link
    name="Leg_lower_4">
    <inertial>
      <origin
        xyz="0.00199999999999988 -7.78388358881055E-06 -0.0300438332087987"
        rpy="0 0 0" />
      <mass
        value="0.00601286144806056" />
      <inertia
        ixx="3.40666556057305E-06"
        ixy="0"
        ixz="6.15091503494431E-21"
        iyy="3.28657694411921E-06"
        iyz="1.35078946160943E-07"
        izz="1.34649215702956E-07" />
    </inertial>
    <visual>
      <origin
        xyz="0 0 0"
        rpy="0 0 0" />
      <geometry>
        <mesh
          filename="package://TLA_Spider.SLDASM/meshes/Leg_lower_4.STL" />
      </geometry>
      <material
        name="">
        <color
          rgba="0.752941176470588 0.752941176470588 0.752941176470588 1" />
      </material>
    </visual>
    <collision>
      <origin
        xyz="0 0 0"
        rpy="0 0 0" />
      <geometry>
        <mesh
          filename="package://TLA_Spider.SLDASM/meshes/Leg_lower_4.STL" />
      </geometry>
    </collision>
  </link>
  <joint
    name="Leg_lower_4"
    type="fixed">
    <origin
      xyz="-0.0041 0 -0.042"
      rpy="-1.1532 0 0" />
    <parent
      link="Shaft_4" />
    <child
      link="Leg_lower_4" />
    <axis
      xyz="0 0 0" />
  </joint>
</robot>