<?xml version="1.0" encoding="utf-8"?>
<!-- This URDF was automatically created by SolidWorks to URDF Exporter! Originally created by Stephen Brawner (brawner@gmail.com) 
     Commit Version: 1.6.0-4-g7f85cfe  Build Version: 1.6.7995.38578
     For more information, please see http://wiki.ros.org/sw_urdf_exporter -->
<robot
  name="TLA_Spider.SLDASM">
  <link
    name="base_link">
    <inertial>
      <origin
        xyz="0.0266892943143008 0.0363292392541809 0.0529146307622766"
        rpy="0 0 0" />
      <mass
        value="0.0921702413076557" />
      <inertia
        ixx="2.08625964058626E-05"
        ixy="-4.27199153271975E-13"
        ixz="3.28311314707858E-11"
        iyy="3.53797936296955E-05"
        iyz="-1.50853658914637E-11"
        izz="2.06809503924717E-05" />
    </inertial>
    <visual>
      <origin
        xyz="0 0 0"
        rpy="0 0 0" />
      <geometry>
        <mesh
          filename="package://TLA_Spider.SLDASM/meshes/base_link.STL" />
      </geometry>
      <material
        name="">
        <color
          rgba="0.752941176470588 0.752941176470588 0.752941176470588 1" />
      </material>
    </visual>
    <collision>
      <origin
        xyz="0 0 0"
        rpy="0 0 0" />
      <geometry>
        <mesh
          filename="package://TLA_Spider.SLDASM/meshes/base_link.STL" />
      </geometry>
    </collision>
  </link>
  <link
    name="Leg_upper_1">
    <inertial>
      <origin
        xyz="0.0224502367111122 0.0194345019150153 0.00090034332669231"
        rpy="0 0 0" />
      <mass
        value="0.0300293940697978" />
      <inertia
        ixx="1.2665786697455E-06"
        ixy="9.5921077131525E-08"
        ixz="5.1688821222679E-08"
        iyy="2.9250097564602E-06"
        iyz="1.10408489647132E-08"
        izz="2.37163561679082E-06" />
    </inertial>
    <visual>
      <origin
        xyz="0 0 0"
        rpy="0 0 0" />
      <geometry>
        <mesh
          filename="package://TLA_Spider.SLDASM/meshes/Leg_upper_1.STL" />
      </geometry>
      <material
        name="">
        <color
          rgba="0.752941176470588 0.752941176470588 0.752941176470588 1" />
      </material>
    </visual>
    <collision>
      <origin
        xyz="0 0 0"
        rpy="0 0 0" />
      <geometry>
        <mesh
          filename="package://TLA_Spider.SLDASM/meshes/Leg_upper_1.STL" />
      </geometry>
    </collision>
  </link>
  <joint
    name="Leg_upper_1"
    type="continuous">
    <origin
      xyz="0.055831 -0.082057 0.032257"
      rpy="1.5708 0 -0.77035" />
    <parent
      link="base_link" />
    <child
      link="Leg_upper_1" />
    <axis
      xyz="0 1 0" />
  </joint>
  <link
    name="Leg_lower_1">
    <inertial>
      <origin
        xyz="0.00210000000000017 0.012165810326122 -0.0100062693519417"
        rpy="0 0 0" />
      <mass
        value="0.00601286144806057" />
      <inertia
        ixx="3.40666556057306E-06"
        ixy="3.17637355220363E-22"
        ixz="4.10281583826302E-22"
        iyy="3.28657694411922E-06"
        iyz="1.35078946160936E-07"
        izz="1.34649215702956E-07" />
    </inertial>
    <visual>
      <origin
        xyz="0 0 0"
        rpy="0 0 0" />
      <geometry>
        <mesh
          filename="package://TLA_Spider.SLDASM/meshes/Leg_lower_1.STL" />
      </geometry>
      <material
        name="">
        <color
          rgba="0.752941176470588 0.752941176470588 0.752941176470588 1" />
      </material>
    </visual>
    <collision>
      <origin
        xyz="0 0 0"
        rpy="0 0 0" />
      <geometry>
        <mesh
          filename="package://TLA_Spider.SLDASM/meshes/Leg_lower_1.STL" />
      </geometry>
    </collision>
  </link>
  <joint
    name="Leg_lower_1"
    type="continuous">
    <origin
      xyz="0.0550943670538194 0.0131500000000004 0"
      rpy="-0.181875741727454 -1.57079631189374 -0.949890242088311" />
    <parent
      link="Leg_upper_1" />
    <child
      link="Leg_lower_1" />
    <axis
      xyz="1 0 0" />
  </joint>
  <link
    name="Leg_upper_2">
    <inertial>
      <origin
        xyz="0.022452620856369 0.0194345020419802 -0.000924342875778729"
        rpy="0 0 0" />
      <mass
        value="0.0300293937966342" />
      <inertia
        ixx="1.26657867093794E-06"
        ixy="9.60379849697742E-08"
        ixz="-4.96153197145248E-08"
        iyy="2.92500973388879E-06"
        iyz="-1.10093963499909E-08"
        izz="2.37163559360178E-06" />
    </inertial>
    <visual>
      <origin
        xyz="0 0 0"
        rpy="0 0 0" />
      <geometry>
        <mesh
          filename="package://TLA_Spider.SLDASM/meshes/Leg_upper_2.STL" />
      </geometry>
      <material
        name="">
        <color
          rgba="0.752941176470588 0.752941176470588 0.752941176470588 1" />
      </material>
    </visual>
    <collision>
      <origin
        xyz="0 0 0"
        rpy="0 0 0" />
      <geometry>
        <mesh
          filename="package://TLA_Spider.SLDASM/meshes/Leg_upper_2.STL" />
      </geometry>
    </collision>
  </link>
  <joint
    name="Leg_upper_2"
    type="continuous">
    <origin
      xyz="-0.0024528 -0.082057 0.032257"
      rpy="1.5708 0 -2.3483" />
    <parent
      link="base_link" />
    <child
      link="Leg_upper_2" />
    <axis
      xyz="0 1 0" />
  </joint>
  <link
    name="Leg_lower_2">
    <inertial>
      <origin
        xyz="-0.00210000000000123 0.0121658103261213 -0.0100062693519433"
        rpy="0 0 0" />
      <mass
        value="0.00601286144806057" />
      <inertia
        ixx="3.40666556057306E-06"
        ixy="5.29395592033938E-22"
        ixz="-5.06234534882453E-22"
        iyy="3.28657694411922E-06"
        iyz="1.35078946160937E-07"
        izz="1.34649215702956E-07" />
    </inertial>
    <visual>
      <origin
        xyz="0 0 0"
        rpy="0 0 0" />
      <geometry>
        <mesh
          filename="package://TLA_Spider.SLDASM/meshes/Leg_lower_2.STL" />
      </geometry>
      <material
        name="">
        <color
          rgba="0.752941176470588 0.752941176470588 0.752941176470588 1" />
      </material>
    </visual>
    <collision>
      <origin
        xyz="0 0 0"
        rpy="0 0 0" />
      <geometry>
        <mesh
          filename="package://TLA_Spider.SLDASM/meshes/Leg_lower_2.STL" />
      </geometry>
    </collision>
  </link>
  <joint
    name="Leg_lower_2"
    type="continuous">
    <origin
      xyz="0.055094 0.01315 0"
      rpy="-1.4305 -1.5708 0.32021" />
    <parent
      link="Leg_upper_2" />
    <child
      link="Leg_lower_2" />
    <axis
      xyz="1 0 0" />
  </joint>
  <link
    name="Leg_upper_3">
    <inertial>
      <origin
        xyz="0.0224502375654233 0.0194345017775579 0.000900343569762558"
        rpy="0 0 0" />
      <mass
        value="0.0300293927667882" />
      <inertia
        ixx="1.26657848366491E-06"
        ixy="9.59211621961702E-08"
        ixz="5.16891106566128E-08"
        iyy="2.92500965669971E-06"
        iyz="1.10408873907466E-08"
        izz="2.37163567100989E-06" />
    </inertial>
    <visual>
      <origin
        xyz="0 0 0"
        rpy="0 0 0" />
      <geometry>
        <mesh
          filename="package://TLA_Spider.SLDASM/meshes/Leg_upper_3.STL" />
      </geometry>
      <material
        name="">
        <color
          rgba="0.752941176470588 0.752941176470588 0.752941176470588 1" />
      </material>
    </visual>
    <collision>
      <origin
        xyz="0 0 0"
        rpy="0 0 0" />
      <geometry>
        <mesh
          filename="package://TLA_Spider.SLDASM/meshes/Leg_upper_3.STL" />
      </geometry>
    </collision>
  </link>
  <joint
    name="Leg_upper_3"
    type="continuous">
    <origin
      xyz="-0.0024528 -0.023773 0.032257"
      rpy="1.5708 0 2.4454" />
    <parent
      link="base_link" />
    <child
      link="Leg_upper_3" />
    <axis
      xyz="0 1 0" />
  </joint>
  <link
    name="Leg_lower_3">
    <inertial>
      <origin
        xyz="0.00210000000000702 0.012165810326125 -0.0100062693519448"
        rpy="0 0 0" />
      <mass
        value="0.00601286144806057" />
      <inertia
        ixx="3.40666556057306E-06"
        ixy="-1.05879118406788E-22"
        ixz="2.35581038455102E-21"
        iyy="3.28657694411922E-06"
        iyz="1.35078946160932E-07"
        izz="1.34649215702955E-07" />
    </inertial>
    <visual>
      <origin
        xyz="0 0 0"
        rpy="0 0 0" />
      <geometry>
        <mesh
          filename="package://TLA_Spider.SLDASM/meshes/Leg_lower_3.STL" />
      </geometry>
      <material
        name="">
        <color
          rgba="0.752941176470588 0.752941176470588 0.752941176470588 1" />
      </material>
    </visual>
    <collision>
      <origin
        xyz="0 0 0"
        rpy="0 0 0" />
      <geometry>
        <mesh
          filename="package://TLA_Spider.SLDASM/meshes/Leg_lower_3.STL" />
      </geometry>
    </collision>
  </link>
  <joint
    name="Leg_lower_3"
    type="continuous">
    <origin
      xyz="0.055094 0.01315 0"
      rpy="2.1537 -1.5708 0" />
    <parent
      link="Leg_upper_3" />
    <child
      link="Leg_lower_3" />
    <axis
      xyz="1 0 0" />
  </joint>
  <link
    name="Leg_upper_4">
    <inertial>
      <origin
        xyz="0.02245262071455 0.0194345020308013 -0.000924342906686859"
        rpy="0 0 0" />
      <mass
        value="0.0300293936383057" />
      <inertia
        ixx="1.26657865028193E-06"
        ixy="9.60379746806071E-08"
        ixz="-4.96152822555382E-08"
        iyy="2.9250097246447E-06"
        iyz="-1.1009400818743E-08"
        izz="2.3716356013859E-06" />
    </inertial>
    <visual>
      <origin
        xyz="0 0 0"
        rpy="0 0 0" />
      <geometry>
        <mesh
          filename="package://TLA_Spider.SLDASM/meshes/Leg_upper_4.STL" />
      </geometry>
      <material
        name="">
        <color
          rgba="0.752941176470588 0.752941176470588 0.752941176470588 1" />
      </material>
    </visual>
    <collision>
      <origin
        xyz="0 0 0"
        rpy="0 0 0" />
      <geometry>
        <mesh
          filename="package://TLA_Spider.SLDASM/meshes/Leg_upper_4.STL" />
      </geometry>
    </collision>
  </link>
  <joint
    name="Leg_upper_4"
    type="continuous">
    <origin
      xyz="0.055831 -0.023773 0.032257"
      rpy="1.5708 0 0.80024" />
    <parent
      link="base_link" />
    <child
      link="Leg_upper_4" />
    <axis
      xyz="0 1 0" />
  </joint>
  <link
    name="Leg_lower_4">
    <inertial>
      <origin
        xyz="-0.00210000000000087 0.0121658103261225 -0.0100062693519418"
        rpy="0 0 0" />
      <mass
        value="0.00601286144806057" />
      <inertia
        ixx="3.40666556057306E-06"
        ixy="-1.05879118406788E-22"
        ixz="6.07812314103965E-21"
        iyy="3.28657694411922E-06"
        iyz="1.35078946160944E-07"
        izz="1.34649215702956E-07" />
    </inertial>
    <visual>
      <origin
        xyz="0 0 0"
        rpy="0 0 0" />
      <geometry>
        <mesh
          filename="package://TLA_Spider.SLDASM/meshes/Leg_lower_4.STL" />
      </geometry>
      <material
        name="">
        <color
          rgba="0.752941176470588 0.752941176470588 0.752941176470588 1" />
      </material>
    </visual>
    <collision>
      <origin
        xyz="0 0 0"
        rpy="0 0 0" />
      <geometry>
        <mesh
          filename="package://TLA_Spider.SLDASM/meshes/Leg_lower_4.STL" />
      </geometry>
    </collision>
  </link>
  <joint
    name="Leg_lower_4"
    type="continuous">
    <origin
      xyz="0.055094 0.01315 0"
      rpy="2.015 -1.5708 0" />
    <parent
      link="Leg_upper_4" />
    <child
      link="Leg_lower_4" />
    <axis
      xyz="1 0 0" />
  </joint>
</robot>