<?xml version="1.0" encoding="utf-8"?>
<!-- This URDF was automatically created by SolidWorks to URDF Exporter! Originally created by Stephen Brawner (brawner@gmail.com) 
     Commit Version: 1.6.0-4-g7f85cfe  Build Version: 1.6.7995.38578
     For more information, please see http://wiki.ros.org/sw_urdf_exporter -->
<robot
  name="spider-viz">
  <link
    name="base_link">
    <inertial>
      <origin
        xyz="0.026689299239783 0.0353671775643985 0.0529145953629847"
        rpy="0 0 0" />
      <mass
        value="0.0501529793920895" />
      <inertia
        ixx="1.78229367251438E-05"
        ixy="-4.18822702263747E-13"
        ixz="3.21873837985511E-11"
        iyy="3.35315521644305E-05"
        iyz="-1.47895744012833E-11"
        izz="1.764485239829E-05" />
    </inertial>
    <visual>
      <origin
        xyz="0 0 0"
        rpy="0 0 0" />
      <geometry>
        <mesh
          filename="package://spider-viz/meshes/base_link.STL" />
      </geometry>
      <material
        name="">
        <color
          rgba="0.792156862745098 0.819607843137255 0.933333333333333 1" />
      </material>
    </visual>
    <collision>
      <origin
        xyz="0 0 0"
        rpy="0 0 0" />
      <geometry>
        <mesh
          filename="package://spider-viz/meshes/base_link.STL" />
      </geometry>
    </collision>
  </link>
  <link
    name="upper_11">
    <inertial>
      <origin
        xyz="0.021593 0.016864 -0.00042693"
        rpy="0 0 0" />
      <mass
        value="0.014321" />
      <inertia
        ixx="5.4813E-07"
        ixy="9.3142E-08"
        ixz="5.0103E-08"
        iyy="2.0485E-06"
        iyz="6.469E-10"
        izz="1.9181E-06" />
    </inertial>
    <visual>
      <origin
        xyz="0 0 0"
        rpy="0 0 0" />
      <geometry>
        <mesh
          filename="package://spider-viz/meshes/upper_11.STL" />
      </geometry>
      <material
        name="">
        <color
          rgba="0.79216 0.81961 0.93333 1" />
      </material>
    </visual>
    <collision>
      <origin
        xyz="0 0 0"
        rpy="0 0 0" />
      <geometry>
        <mesh
          filename="package://spider-viz/meshes/upper_11.STL" />
      </geometry>
    </collision>
  </link>
  <joint
    name="upper_11"
    type="continuous">
    <origin
      xyz="0.055831 -0.023773 0.032257"
      rpy="1.5708 0 0.7854" />
    <parent
      link="base_link" />
    <child
      link="upper_11" />
    <axis
      xyz="0 1 0" />
  </joint>
  <link
    name="lower_11">
    <inertial>
      <origin
        xyz="0.0021 0.012165 -0.014493"
        rpy="0 0 0" />
      <mass
        value="0.005129" />
      <inertia
        ixx="3.335E-06"
        ixy="-4.2352E-22"
        ixz="-5.3866E-21"
        iyy="3.2193E-06"
        iyz="1.3243E-07"
        izz="1.2919E-07" />
    </inertial>
    <visual>
      <origin
        xyz="0 0 0"
        rpy="0 0 0" />
      <geometry>
        <mesh
          filename="package://spider-viz/meshes/lower_11.STL" />
      </geometry>
      <material
        name="">
        <color
          rgba="0.79216 0.81961 0.93333 1" />
      </material>
    </visual>
    <collision>
      <origin
        xyz="0 0 0"
        rpy="0 0 0" />
      <geometry>
        <mesh
          filename="package://spider-viz/meshes/lower_11.STL" />
      </geometry>
    </collision>
  </link>
  <joint
    name="lower_11"
    type="continuous">
    <origin
      xyz="0.055094 0.01315 0"
      rpy="1.5708 -1.5708 0" />
    <parent
      link="upper_11" />
    <child
      link="lower_11" />
    <axis
      xyz="1 0 0" />
  </joint>
  <link
    name="upper_21">
    <inertial>
      <origin
        xyz="0.0214983562340349 0.0168643531779405 -0.000426932215157508"
        rpy="0 0 0" />
      <mass
        value="0.0143208814059842" />
      <inertia
        ixx="5.48127854126058E-07"
        ixy="9.31421363318193E-08"
        ixz="5.01027099645457E-08"
        iyy="2.04847757519697E-06"
        iyz="6.46897357285905E-10"
        izz="1.91806749909677E-06" />
    </inertial>
    <visual>
      <origin
        xyz="0 0 0"
        rpy="0 0 0" />
      <geometry>
        <mesh
          filename="package://spider-viz/meshes/upper_21.STL" />
      </geometry>
      <material
        name="">
        <color
          rgba="0.792156862745098 0.819607843137255 0.933333333333333 1" />
      </material>
    </visual>
    <collision>
      <origin
        xyz="0 0 0"
        rpy="0 0 0" />
      <geometry>
        <mesh
          filename="package://spider-viz/meshes/upper_21.STL" />
      </geometry>
    </collision>
  </link>
  <joint
    name="upper_21"
    type="continuous">
    <origin
      xyz="-0.0024528 -0.082057 0.032257"
      rpy="1.5708 0 -2.3562" />
    <parent
      link="base_link" />
    <child
      link="upper_21" />
    <axis
      xyz="0 1 0" />
  </joint>
  <link
    name="lower_21">
    <inertial>
      <origin
        xyz="0.0021 0.012165 -0.014493"
        rpy="0 0 0" />
      <mass
        value="0.005129" />
      <inertia
        ixx="3.335E-06"
        ixy="2.1176E-22"
        ixz="-1.0588E-22"
        iyy="3.2193E-06"
        iyz="1.3243E-07"
        izz="1.2919E-07" />
    </inertial>
    <visual>
      <origin
        xyz="0 0 0"
        rpy="0 0 0" />
      <geometry>
        <mesh
          filename="package://spider-viz/meshes/lower_21.STL" />
      </geometry>
      <material
        name="">
        <color
          rgba="0.79216 0.81961 0.93333 1" />
      </material>
    </visual>
    <collision>
      <origin
        xyz="0 0 0"
        rpy="0 0 0" />
      <geometry>
        <mesh
          filename="package://spider-viz/meshes/lower_21.STL" />
      </geometry>
    </collision>
  </link>
  <joint
    name="lower_21"
    type="continuous">
    <origin
      xyz="0.0550000000000001 0.0131500000000001 0"
      rpy="1.5707963267949 -1.5707963267949 0" />
    <parent
      link="upper_21" />
    <child
      link="lower_21" />
    <axis
      xyz="1 0 0" />
  </joint>
  <link
    name="upper_32">
    <inertial>
      <origin
        xyz="0.062807 0.066864 0.041622"
        rpy="0 0 0" />
      <mass
        value="0.014321" />
      <inertia
        ixx="5.4813E-07"
        ixy="9.3172E-08"
        ixz="-4.9215E-08"
        iyy="2.0485E-06"
        iyz="-6.3512E-10"
        izz="1.9181E-06" />
    </inertial>
    <visual>
      <origin
        xyz="0 0 0"
        rpy="0 0 0" />
      <geometry>
        <mesh
          filename="package://spider-viz/meshes/upper_32.STL" />
      </geometry>
      <material
        name="">
        <color
          rgba="0.79216 0.81961 0.93333 1" />
      </material>
    </visual>
    <collision>
      <origin
        xyz="0 0 0"
        rpy="0 0 0" />
      <geometry>
        <mesh
          filename="package://spider-viz/meshes/upper_32.STL" />
      </geometry>
    </collision>
  </link>
  <joint
    name="upper_32"
    type="continuous">
    <origin
      xyz="0.0558314237945951 -0.0237725392912399 -0.0177425873419207"
      rpy="1.5707963267949 0 -0.785398163397447" />
    <parent
      link="base_link" />
    <child
      link="upper_32" />
    <axis
      xyz="0 1 0" />
  </joint>
  <link
    name="lower_32">
    <inertial>
      <origin
        xyz="5.68989300120393E-16 0.0121646478740793 -0.014493041910956"
        rpy="0 0 0" />
      <mass
        value="0.00512899375178834" />
      <inertia
        ixx="3.33501926217674E-06"
        ixy="2.11758236813575E-22"
        ixz="-1.11426571247317E-21"
        iyy="3.21931643357581E-06"
        iyz="1.32430339373467E-07"
        izz="1.29191209638301E-07" />
    </inertial>
    <visual>
      <origin
        xyz="0 0 0"
        rpy="0 0 0" />
      <geometry>
        <mesh
          filename="package://spider-viz/meshes/lower_32.STL" />
      </geometry>
      <material
        name="">
        <color
          rgba="0.792156862745098 0.819607843137255 0.933333333333333 1" />
      </material>
    </visual>
    <collision>
      <origin
        xyz="0 0 0"
        rpy="0 0 0" />
      <geometry>
        <mesh
          filename="package://spider-viz/meshes/lower_32.STL" />
      </geometry>
    </collision>
  </link>
  <joint
    name="lower_32"
    type="continuous">
    <origin
      xyz="0.096308 0.06315 0.039113"
      rpy="1.5708 -1.5708 0" />
    <parent
      link="upper_32" />
    <child
      link="lower_32" />
    <axis
      xyz="1 0 0" />
  </joint>
  <link
    name="upper_42">
    <inertial>
      <origin
        xyz="0.062807 -0.033136 0.041622"
        rpy="0 0 0" />
      <mass
        value="0.014321" />
      <inertia
        ixx="5.4813E-07"
        ixy="9.3172E-08"
        ixz="-4.9215E-08"
        iyy="2.0485E-06"
        iyz="-6.3512E-10"
        izz="1.9181E-06" />
    </inertial>
    <visual>
      <origin
        xyz="0 0 0"
        rpy="0 0 0" />
      <geometry>
        <mesh
          filename="package://spider-viz/meshes/upper_42.STL" />
      </geometry>
      <material
        name="">
        <color
          rgba="0.79216 0.81961 0.93333 1" />
      </material>
    </visual>
    <collision>
      <origin
        xyz="0 0 0"
        rpy="0 0 0" />
      <geometry>
        <mesh
          filename="package://spider-viz/meshes/upper_42.STL" />
      </geometry>
    </collision>
  </link>
  <joint
    name="upper_42"
    type="continuous">
    <origin
      xyz="-0.0024528 -0.082057 0.082257"
      rpy="1.5708 0 2.3562" />
    <parent
      link="base_link" />
    <child
      link="upper_42" />
    <axis
      xyz="0 1 0" />
  </joint>
  <link
    name="lower_42">
    <inertial>
      <origin
        xyz="3.1225E-17 0.012165 -0.014493"
        rpy="0 0 0" />
      <mass
        value="0.005129" />
      <inertia
        ixx="3.335E-06"
        ixy="-3.1764E-22"
        ixz="3.2161E-21"
        iyy="3.2193E-06"
        iyz="1.3243E-07"
        izz="1.2919E-07" />
    </inertial>
    <visual>
      <origin
        xyz="0 0 0"
        rpy="0 0 0" />
      <geometry>
        <mesh
          filename="package://spider-viz/meshes/lower_42.STL" />
      </geometry>
      <material
        name="">
        <color
          rgba="0.79216 0.81961 0.93333 1" />
      </material>
    </visual>
    <collision>
      <origin
        xyz="0 0 0"
        rpy="0 0 0" />
      <geometry>
        <mesh
          filename="package://spider-viz/meshes/lower_42.STL" />
      </geometry>
    </collision>
  </link>
  <joint
    name="lower_42"
    type="continuous">
    <origin
      xyz="0.096308 -0.03685 0.048063"
      rpy="1.5708 -1.5708 0" />
    <parent
      link="upper_42" />
    <child
      link="lower_42" />
    <axis
      xyz="1 0 0" />
  </joint>
</robot>