<?xml version="1.0" encoding="utf-8"?>
<!-- This URDF was automatically created by SolidWorks to URDF Exporter! Originally created by Stephen Brawner (brawner@gmail.com) 
     Commit Version: 1.6.0-4-g7f85cfe  Build Version: 1.6.7995.38578
     For more information, please see http://wiki.ros.org/sw_urdf_exporter -->
<robot
  name="spider-viz">
  <link
    name="base_link">
    <inertial>
      <origin
        xyz="0.026689299239783 -0.0529145953629847 0.0353671775643985"
        rpy="0 0 0" />
      <mass
        value="0.0501529793920895" />
      <inertia
        ixx="1.78229367251438E-05"
        ixy="-3.21873837988952E-11"
        ixz="-4.18822702149728E-13"
        iyy="1.764485239829E-05"
        iyz="1.47895744024287E-11"
        izz="3.35315521644305E-05" />
    </inertial>
    <visual>
      <origin
        xyz="0 0 0"
        rpy="0 0 0" />
      <geometry>
        <mesh
          filename="package://spider-viz/meshes/base_link.STL" />
      </geometry>
      <material
        name="">
        <color
          rgba="0.792156862745098 0.819607843137255 0.933333333333333 1" />
      </material>
    </visual>
    <collision>
      <origin
        xyz="0 0 0"
        rpy="0 0 0" />
      <geometry>
        <mesh
          filename="package://spider-viz/meshes/base_link.STL" />
      </geometry>
    </collision>
  </link>
  <link
    name="upper_11">
    <inertial>
      <origin
        xyz="0.0215927232878543 0.0168643531779406 -0.000426932215157494"
        rpy="0 0 0" />
      <mass
        value="0.0143208814059843" />
      <inertia
        ixx="5.48127854126058E-07"
        ixy="9.31421363318178E-08"
        ixz="5.01027099645457E-08"
        iyy="2.04847757519697E-06"
        iyz="6.46897357285978E-10"
        izz="1.91806749909677E-06" />
    </inertial>
    <visual>
      <origin
        xyz="0 0 0"
        rpy="0 0 0" />
      <geometry>
        <mesh
          filename="package://spider-viz/meshes/upper_11.STL" />
      </geometry>
      <material
        name="">
        <color
          rgba="0.792156862745098 0.819607843137255 0.933333333333333 1" />
      </material>
    </visual>
    <collision>
      <origin
        xyz="0 0 0"
        rpy="0 0 0" />
      <geometry>
        <mesh
          filename="package://spider-viz/meshes/upper_11.STL" />
      </geometry>
    </collision>
  </link>
  <joint
    name="upper_11"
    type="continuous">
    <origin
      xyz="0.055831423794595 -0.0237725392912399 0.0322574126580793"
      rpy="1.5707963267949 0 0.785398163397433" />
    <parent
      link="base_link" />
    <child
      link="upper_11" />
    <axis
      xyz="0 1 0" />
  </joint>
  <link
    name="lower_11">
    <inertial>
      <origin
        xyz="0.0021 0.012164647874079 -0.0144930419109557"
        rpy="0 0 0" />
      <mass
        value="0.00512899375178834" />
      <inertia
        ixx="3.33501926217674E-06"
        ixy="-4.2351647362715E-22"
        ixz="-5.39983503874616E-21"
        iyy="3.21931643357581E-06"
        iyz="1.32430339373461E-07"
        izz="1.291912096383E-07" />
    </inertial>
    <visual>
      <origin
        xyz="0 0 0"
        rpy="0 0 0" />
      <geometry>
        <mesh
          filename="package://spider-viz/meshes/lower_11.STL" />
      </geometry>
      <material
        name="">
        <color
          rgba="0.792156862745098 0.819607843137255 0.933333333333333 1" />
      </material>
    </visual>
    <collision>
      <origin
        xyz="0 0 0"
        rpy="0 0 0" />
      <geometry>
        <mesh
          filename="package://spider-viz/meshes/lower_11.STL" />
      </geometry>
    </collision>
  </link>
  <joint
    name="lower_11"
    type="continuous">
    <origin
      xyz="0.0550943670538194 0.0131500000000002 0"
      rpy="1.5707963267949 -1.5707963267949 0" />
    <parent
      link="upper_11" />
    <child
      link="lower_11" />
    <axis
      xyz="1 0 0" />
  </joint>
  <link
    name="upper_21">
    <inertial>
      <origin
        xyz="0.0214983562340349 0.0168643531779405 -0.000426932215157515"
        rpy="0 0 0" />
      <mass
        value="0.0143208814059842" />
      <inertia
        ixx="5.48127854126058E-07"
        ixy="9.31421363318193E-08"
        ixz="5.01027099645456E-08"
        iyy="2.04847757519697E-06"
        iyz="6.46897357285955E-10"
        izz="1.91806749909677E-06" />
    </inertial>
    <visual>
      <origin
        xyz="0 0 0"
        rpy="0 0 0" />
      <geometry>
        <mesh
          filename="package://spider-viz/meshes/upper_21.STL" />
      </geometry>
      <material
        name="">
        <color
          rgba="0.792156862745098 0.819607843137255 0.933333333333333 1" />
      </material>
    </visual>
    <collision>
      <origin
        xyz="0 0 0"
        rpy="0 0 0" />
      <geometry>
        <mesh
          filename="package://spider-viz/meshes/upper_21.STL" />
      </geometry>
    </collision>
  </link>
  <joint
    name="upper_21"
    type="continuous">
    <origin
      xyz="-0.00245284745286621 -0.0820568105387026 0.0322574126580794"
      rpy="1.5707963267949 0 -2.35619449019236" />
    <parent
      link="base_link" />
    <child
      link="upper_21" />
    <axis
      xyz="0 1 0" />
  </joint>
  <link
    name="lower_21">
    <inertial>
      <origin
        xyz="0.00210000000000009 0.0121646478740791 -0.014493041910956"
        rpy="0 0 0" />
      <mass
        value="0.00512899375178834" />
      <inertia
        ixx="3.33501926217674E-06"
        ixy="2.11758236813575E-22"
        ixz="-1.19114008207636E-22"
        iyy="3.21931643357581E-06"
        iyz="1.32430339373467E-07"
        izz="1.29191209638301E-07" />
    </inertial>
    <visual>
      <origin
        xyz="0 0 0"
        rpy="0 0 0" />
      <geometry>
        <mesh
          filename="package://spider-viz/meshes/lower_21.STL" />
      </geometry>
      <material
        name="">
        <color
          rgba="0.792156862745098 0.819607843137255 0.933333333333333 1" />
      </material>
    </visual>
    <collision>
      <origin
        xyz="0 0 0"
        rpy="0 0 0" />
      <geometry>
        <mesh
          filename="package://spider-viz/meshes/lower_21.STL" />
      </geometry>
    </collision>
  </link>
  <joint
    name="lower_21"
    type="continuous">
    <origin
      xyz="0.0550000000000001 0.0131500000000001 0"
      rpy="1.5707963267949 -1.5707963267949 0" />
    <parent
      link="upper_21" />
    <child
      link="lower_21" />
    <axis
      xyz="1 0 0" />
  </joint>
  <link
    name="upper_32">
    <inertial>
      <origin
        xyz="0.0215939860640953 0.0168643533273595 0.000408310357846983"
        rpy="0 0 0" />
      <mass
        value="0.0143208810051291" />
      <inertia
        ixx="5.48127835188724E-07"
        ixy="9.31716682522592E-08"
        ixz="-4.92150374061604E-08"
        iyy="2.04847754555167E-06"
        iyz="-6.35115992521145E-10"
        izz="1.91806748542429E-06" />
    </inertial>
    <visual>
      <origin
        xyz="0 0 0"
        rpy="0 0 0" />
      <geometry>
        <mesh
          filename="package://spider-viz/meshes/upper_32.STL" />
      </geometry>
      <material
        name="">
        <color
          rgba="0.792156862745098 0.819607843137255 0.933333333333333 1" />
      </material>
    </visual>
    <collision>
      <origin
        xyz="0 0 0"
        rpy="0 0 0" />
      <geometry>
        <mesh
          filename="package://spider-viz/meshes/upper_32.STL" />
      </geometry>
    </collision>
  </link>
  <joint
    name="upper_32"
    type="continuous">
    <origin
      xyz="0.0558314237945942 -0.082056810538703 0.032257412658079"
      rpy="1.5707963267949 0 -0.785398163397447" />
    <parent
      link="base_link" />
    <child
      link="upper_32" />
    <axis
      xyz="0 1 0" />
  </joint>
  <link
    name="lower_32">
    <inertial>
      <origin
        xyz="5.68989300120393E-16 0.0121646478740792 -0.014493041910956"
        rpy="0 0 0" />
      <mass
        value="0.00512899375178834" />
      <inertia
        ixx="3.33501926217674E-06"
        ixy="2.11758236813575E-22"
        ixz="-1.10764826757275E-21"
        iyy="3.21931643357581E-06"
        iyz="1.32430339373467E-07"
        izz="1.29191209638301E-07" />
    </inertial>
    <visual>
      <origin
        xyz="0 0 0"
        rpy="0 0 0" />
      <geometry>
        <mesh
          filename="package://spider-viz/meshes/lower_32.STL" />
      </geometry>
      <material
        name="">
        <color
          rgba="0.792156862745098 0.819607843137255 0.933333333333333 1" />
      </material>
    </visual>
    <collision>
      <origin
        xyz="0 0 0"
        rpy="0 0 0" />
      <geometry>
        <mesh
          filename="package://spider-viz/meshes/lower_32.STL" />
      </geometry>
    </collision>
  </link>
  <joint
    name="lower_32"
    type="continuous">
    <origin
      xyz="0.0550943670538193 0.0131500000000003 -0.00210000000000139"
      rpy="1.5707963267949 -1.5707963267949 0" />
    <parent
      link="upper_32" />
    <child
      link="lower_32" />
    <axis
      xyz="1 0 0" />
  </joint>
  <link
    name="upper_42">
    <inertial>
      <origin
        xyz="0.0215939860640953 0.0168643533273594 0.000408310357846806"
        rpy="0 0 0" />
      <mass
        value="0.0143208810051291" />
      <inertia
        ixx="5.48127835188725E-07"
        ixy="9.3171668252259E-08"
        ixz="-4.92150374061618E-08"
        iyy="2.04847754555167E-06"
        iyz="-6.35115992522546E-10"
        izz="1.91806748542429E-06" />
    </inertial>
    <visual>
      <origin
        xyz="0 0 0"
        rpy="0 0 0" />
      <geometry>
        <mesh
          filename="package://spider-viz/meshes/upper_42.STL" />
      </geometry>
      <material
        name="">
        <color
          rgba="0.792156862745098 0.819607843137255 0.933333333333333 1" />
      </material>
    </visual>
    <collision>
      <origin
        xyz="0 0 0"
        rpy="0 0 0" />
      <geometry>
        <mesh
          filename="package://spider-viz/meshes/upper_42.STL" />
      </geometry>
    </collision>
  </link>
  <joint
    name="upper_42"
    type="continuous">
    <origin
      xyz="-0.00245284745286684 -0.0237725392912402 0.0322574126580794"
      rpy="1.5707963267949 0 2.35619449019235" />
    <parent
      link="base_link" />
    <child
      link="upper_42" />
    <axis
      xyz="0 1 0" />
  </joint>
  <link
    name="lower_42">
    <inertial>
      <origin
        xyz="3.12250225675825E-17 0.0121646478740791 -0.0144930419109558"
        rpy="0 0 0" />
      <mass
        value="0.00512899375178834" />
      <inertia
        ixx="3.33501926217674E-06"
        ixy="0"
        ixz="3.25578289100872E-21"
        iyy="3.21931643357581E-06"
        iyz="1.32430339373465E-07"
        izz="1.29191209638301E-07" />
    </inertial>
    <visual>
      <origin
        xyz="0 0 0"
        rpy="0 0 0" />
      <geometry>
        <mesh
          filename="package://spider-viz/meshes/lower_42.STL" />
      </geometry>
      <material
        name="">
        <color
          rgba="0.792156862745098 0.819607843137255 0.933333333333333 1" />
      </material>
    </visual>
    <collision>
      <origin
        xyz="0 0 0"
        rpy="0 0 0" />
      <geometry>
        <mesh
          filename="package://spider-viz/meshes/lower_42.STL" />
      </geometry>
    </collision>
  </link>
  <joint
    name="lower_42"
    type="continuous">
    <origin
      xyz="0.0550943670538194 0.0131500000000001 0.00684999999999963"
      rpy="1.5707963267949 -1.5707963267949 0" />
    <parent
      link="upper_42" />
    <child
      link="lower_42" />
    <axis
      xyz="1 0 0" />
  </joint>
</robot>